<?xml version="1.0"?>
<robot name="bt7R" xmlns:xacro="http://www.ros.org/wiki/xacro">

  <!-- Links -->

  <!-- Map Link -->
  <link name="map"/>

  <!-- Base Link -->
  <link name="base_link">
    <visual>
      <geometry>
        <box size="0.2 0.2 0.2"/>  <!-- Cube with 20cm sides -->
      </geometry>
      <material name="gray">
        <color rgba="0.6 0.6 0.6 1.0"/>
      </material>
    </visual>
  </link>

  <link name="link1" />

  <link name="link2"/>

  <link name="link3">


  <visual>
    <geometry>
      <sphere radius="0.05"/>
    </geometry>
    <material name="white">
      <color rgba="1 1 1 1"/>
    </material>
  </visual>


  <visual>
    <geometry>
      <sphere radius="0.05"/>
    </geometry>
    <origin xyz="0 0 0" rpy="0 0 1.57"/>  
    <material name="black">
      <color rgba="0 0 0 1"/>
    </material>
  </visual>
  </link>

<link name="link4">
    <visual>
      <origin xyz="0 0 -0.275"/> 
      <geometry>
        <cylinder radius="0.05" length="0.55"/>  
      </geometry>
      <material name="blue">
        <color rgba="0 0 1 1"/>
      </material>
    </visual>
  </link>


  <!-- <link name="link1"> -->
    <!-- <visual> -->
      <!-- <origin xyz="0 0 -0.335"/>  Moves the cylinder down -->
      <!-- <geometry> -->
        <!-- <cylinder radius="0.05"  -->
      <!-- </geometry>
      <material name="blue">
        <color rgba="0 0 1 1"/>
      </material>
    </visual>
  </link> -->
  
  <!-- <link name="link2">
    <visual>
    <origin xyz="0 0 0"/>
      <geometry>
        <cylinder radius="0.05" length="0.25"/>
      </geometry>
      <material name="red">
        <color rgba="1 0 0 1"/>
      </material>
    </visual>
  </link> -->

  <!-- <link name="link3">
    <visual>
      <geometry>
        <cylinder radius="0.05" length="0.25"/>
      </geometry>
      <material name="green">
        <color rgba="0 1 0 1"/>
      </material>
    </visual>
  </link> -->
  
  <!-- <link name="link4" />

  <link name="link5"/>

  <link name="link6">
  <visual>
    <geometry>
      <sphere radius="0.05"/>
    </geometry>
    <material name="white">
      <color rgba="1 1 1 1"/>
    </material>
  </visual>

  <visual>
    <geometry>
      <sphere radius="0.05"/>
    </geometry>
    <origin xyz="0 0 0" rpy="0 0 1.57"/>  
    <material name="black">
      <color rgba="0 0 0 1"/>
    </material>
  </visual>
  </link> -->

  <!-- <link name="tool">
    <visual>
      <origin xyz="-0.1 0 0" rpy="0 1.57 0"/>  
      <geometry>
        <cylinder radius="0.01" length="0.2"/> 
      </geometry>
      <material name="silver">
        <color rgba="0.75 0.75 0.75 1"/>
      </material>
    </visual>
  </link> -->

  <!-- Joints-->
  <joint name="map_to_base" type="fixed">
    <parent link="map"/>
    <child link="base_link"/>
    <origin xyz="0 0 0" rpy="0 0 0"/>
    <axis xyz="0 0 1"/>
  </joint>


    <!-- working Joint1 if have -->
  <joint name="joint1" type="revolute">
    <parent link="base_link"/>
    <child link="link1"/>
    <origin xyz="0 0 0" rpy="0 0 0"/>
    <axis xyz="0 0 1"/>
    <limit lower="-1.57" upper="1.57" effort="10" velocity="1.0"/>
  </joint>

  <joint name="joint2" type="revolute">
    <parent link="link1"/>
    <child link="link2"/>
    <origin xyz="0 0 0" rpy="0 0 0"/> 
    <axis xyz="0 1 0"/>
    <limit lower="-1.57" upper="1.57" effort="10" velocity="1.0"/>
  </joint>

  <joint name="joint3" type="revolute">
    <parent link="link2"/>
    <child link="link3"/>
    <origin xyz="0 0 0" rpy="0 0 0"/> 
    <axis xyz="0 0 1"/>
    <limit lower="-1.57" upper="1.57" effort="10" velocity="1.0"/>
  </joint>

  <joint name="joint4" type="revolute">
    <parent link="link3"/>
    <child link="link4"/>
    <origin xyz="0 0 0.55" rpy="0 0 0"/> 
    <axis xyz="0 1 0"/>
    <limit lower="-1.57" upper="1.57" effort="10" velocity="1.0"/>
  </joint>


  <!-- <joint name="link6_to_tool" type="fixed">
    <parent link="link6"/>
    <child link="tool"/>
    <origin xyz="-0.2 0 0" rpy="0 0 0"/>
    <axis xyz="0 0 1"/>
    <limit effort="10.0" velocity="1.0" lower="-1.57" upper="1.57"/>
  </joint> -->

</robot>
